Workbook

Sheet Sheet2
B1: 原价 | C1: 售价 | D1: 差评率 | E1: 星级店铺 | F1: 有无售后服务 | H1: 店铺地理位置 | I1: 有无质检 | J1: 销量 | K1: url
A2: =VLOOKUP(K2,Sheet4!B:C,2,FALSE) -> 思域 | C2: 10.18万 | E2: 1 | F2: 无 | H2: 宁夏银川市贺兰县德胜工业园区汽车大世界德鑫路9号淘车二手车 | I2: 有 | J2: 9.3 | K2: http://www.che168.com/dealer/522686/50975959.html
A3: =VLOOKUP(K3,Sheet4!B:C,2,FALSE) -> 思域 | C3: 7.68万 | E3: 0 | F3: 无 | H3: 东莞市寮步镇富荣路联合二手车交易市场V18号 | I3: 有 | J3: 9.3 | K3: http://www.che168.com/dealer/360661/50234187.html
A4: =VLOOKUP(K4,Sheet4!B:C,2,FALSE) -> 思域 | C4: 4.98万 | E4: 2 | F4: 无 | H4: 广州市番禺区钟村街谢村工业区七街4号 | I4: 有 | J4: 9.3 | K4: http://www.che168.com/dealer/366664/51663344.html
A5: =VLOOKUP(K5,Sheet4!B:C,2,FALSE) -> 思域 | C5: 8.16万 | E5: 1 | F5: 有 | H5: 沈阳市铁西区北二中路6号 星摩尔购物中心G105 | I5: 有 | J5: 9.3 | K5: http://www.che168.com/dealer/349857/51456651.html
A6: =VLOOKUP(K6,Sheet4!B:C,2,FALSE) -> 思域 | C6: 5.64万 | E6: 2 | F6: 无 | H6: 湖南省长沙市长沙县湘龙街道中南汽车世界J11栋 | I6: 有 | J6: 9.3 | K6: http://www.che168.com/dealer/355413/51620390.html
A7: =VLOOKUP(K7,Sheet4!B:C,2,FALSE) -> 思域 | C7: 3.99万 | E7: 0 | F7: 无 | H7: 上海市嘉定区恒翔路255号 | I7: 有 | J7: 9.3 | K7: http://www.che168.com/dealer/302732/51427339.html
A8: =VLOOKUP(K8,Sheet4!B:C,2,FALSE) -> 思域 | C8: 11.28万 | E8: 3 | F8: 有 | H8: 福建省泉州市晋江市陈埭镇花厅口村阳光东路1168号 | I8: 有 | J8: 9.3 | K8: http://www.che168.com/dealer/347357/51728885.html
A9: =VLOOKUP(K9,Sheet4!B:C,2,FALSE) -> 思域 | C9: 6.38万 | E9: 0 | F9: 无 | H9: 心圩街道新村村委会 广西壮族自治区南宁市西乡塘区新村中坡88号 | I9: 有 | J9: 9.3 | K9: http://www.che168.com/dealer/517025/51698768.html
A10: =VLOOKUP(K10,Sheet4!B:C,2,FALSE) -> 思域 | C10: 9.00万 | E10: 1 | F10: 有 | H10: 看车地址以车辆所在地为准 | I10: 有 | J10: 9.3 | K10: http://www.che168.com/dealer/606334/51742318.html
A11: =VLOOKUP(K11,Sheet4!B:C,2,FALSE) -> 思域 | C11: 13.88万 | E11: 0 | F11: 无 | H11: 南京市雨花区卡子门大街68号 | I11: 有 | J11: 9.3 | K11: http://www.che168.com/dealer/343793/50907119.html
A12: =VLOOKUP(K12,Sheet4!B:C,2,FALSE) -> 思域 | C12: 9.88万 | E12: 0 | F12: 有 | H12: 郑州市惠济区天河路英才街格力广场迈卡名车茂C号馆2楼326天跃名车 | I12: 有 | J12: 9.3 | K12: http://www.che168.com/dealer/406545/51645855.html
A13: =VLOOKUP(K13,Sheet4!B:C,2,FALSE) -> 思域 | C13: 7.28万 | E13: 2 | F13: 无 | H13: 合肥市吴山镇―杨庙路与车左路交叉口东南角 | I13: 有 | J13: 9.3 | K13: http://www.che168.com/dealer/478339/51729013.html
... A18: =VLOOKUP(K18,Sheet4!B:C,2,FALSE) -> 思域 | C18: 2.39万 | E18: 2 | F18: 无 | H18: 陕西省西安市长安区东长安街1200号 | I18: 有 | J18: 9.3 | K18: http://www.che168.com/dealer/466721/51686899.html
A19: =VLOOKUP(K19,Sheet4!B:C,2,FALSE) -> 思域 | C19: 7.98万 | E19: 此店铺点不开 | F19: 无 | H19: 无具体地址 | I19: 无 | J19: 无热度 | K19: http://www.che168.com/dealer/179069/51709312.html
A20: =VLOOKUP(K20,Sheet4!B:C,2,FALSE) -> 思域 | C20: 6.95万 | E20: 2 | F20: 有 | H20: 佛山市顺德区伦教街道常教社区伦新路28号新协力汽车贸易大厦4栋2001 | I20: 有 | J20: 9.3 | K20: http://www.che168.com/dealer/595827/51420543.html
A21: =VLOOKUP(K21,Sheet4!B:C,2,FALSE) -> 思域 | C21: 7.98万 | E21: 1 | F21: 无 | H21: 西安市沣东新城天台路39号 | I21: 有 | J21: 9.3 | K21: http://www.che168.com/dealer/413117/51521304.html
A22: =VLOOKUP(K22,Sheet4!B:C,2,FALSE) -> 思域 | C22: 8.88万 | E22: 1 | F22: 无 | H22: 无锡市凤翔路神州汽车城B区B3馆（顺风二手车旗舰店） | I22: 有 | J22: 9.3 | K22: http://www.che168.com/dealer/247261/51740748.html
A23: =VLOOKUP(K23,Sheet4!B:C,2,FALSE) -> 思域 | C23: 9.97万 | E23: 3 | F23: 有 | H23: 上海市浦东新区张江路1160号（近高科西路）张江奥迪售后三楼 | I23: 有 | J23: 9.3 | K23: http://www.che168.com/dealer/145101/51751723.html
A24: =VLOOKUP(K24,Sheet4!B:C,2,FALSE) -> 思域 | C24: 5.58万 | E24: 2 | F24: 有 | H24: 上海市浦东新区沪南路4777号上海车市中楼二层展厅 | I24: 有 | J24: 9.3 | K24: http://www.che168.com/dealer/100947/51180356.html
A25: =VLOOKUP(K25,Sheet4!B:C,2,FALSE) -> 思域 | C25: 7.77万 | E25: 3 | F25: 无 | H25: 重庆巴南区八公里二手车市场 | I25: 有 | J25: 9.3 | K25: http://www.che168.com/dealer/615775/51745904.html
A26: =VLOOKUP(K26,Sheet4!B:C,2,FALSE) -> 思域 | C26: 6.68万 | E26: 0 | F26: 有 | H26: 成都双流区锦和汽车商业中心 | I26: 有 | J26: 9.3 | K26: http://www.che168.com/dealer/615736/51745213.html
A27: =VLOOKUP(K27,Sheet4!B:C,2,FALSE) -> 思域 | C27: 6.98万 | E27: 0 | F27: 无 | H27: 浙江省台州市路桥区新安南街675-679号 | I27: 有 | J27: 9.3 | K27: http://www.che168.com/dealer/600608/51702840.html
A28: =VLOOKUP(K28,Sheet4!B:C,2,FALSE) -> 思域 | C28: 8.38万 | E28: 0 | F28: 无 | H28: 广州市花都区新雅街镜湖大道67号之一B158(众诚车行） | I28: 有 | J28: 9.3 | K28: http://www.che168.com/dealer/421770/51666667.html
C29: 售价 | E29: 星级店铺 | F29: 有无售后服务 | H29: 店铺地理位置 | I29: 有无质检 | J29: 销量 | K29: url
A30: =VLOOKUP(K30,Sheet4!B:C,2,FALSE) -> 奥德赛 | C30: 16.90万 | E30: 1 | F30: 有 | H30: 郑州市惠济区天河路英才街交叉口迈卡名车茂B馆1楼 | I30: 有 | J30: 9.23 | K30: http://www.che168.com/dealer/258082/51730994.html
A31: =VLOOKUP(K31,Sheet4!B:C,2,FALSE) -> 奥德赛 | C31: 9.58万 | E31: 0 | F31: 无 | H31: 城西镇椰海大道361号林安国际商贸城商业街5栋一层商铺 | I31: 有 | J31: 9.23 | K31: http://www.che168.com/dealer/490567/51708046.html
A32: =VLOOKUP(K32,Sheet4!B:C,2,FALSE) -> 奥德赛 | C32: 12.58万 | E32: 2 | F32: 无 | H32: 合肥市吴山镇―杨庙路与车左路交叉口东南角 | I32: 有 | J32: 9.23 | K32: http://www.che168.com/dealer/478339/51735682.html
A33: =VLOOKUP(K33,Sheet4!B:C,2,FALSE) -> 奥德赛 | C33: 22.80万 | E33: 3 | F33: 有 | H33: 福建省泉州市鲤城区洋仕街36号泉州惠丰名车 | I33: 有 | J33: 9.23 | K33: http://www.che168.com/dealer/286456/50412953.html
A34: =VLOOKUP(K34,Sheet4!B:C,2,FALSE) -> 奥德赛 | C34: 17.00万 | E34: 3 | F34: 无 | H34: 福建省泉州市鲤城区洋仕街36号泉州惠丰名车 | I34: 有 | J34: 9.23 | K34: http://www.che168.com/dealer/286456/51463574.html
A35: =VLOOKUP(K35,Sheet4!B:C,2,FALSE) -> 奥德赛 | C35: 23.80万 | E35: 0 | F35: 有 | H35: 哈尔滨道里区城乡路237号 | I35: 有 | J35: 9.23 | K35: http://www.che168.com/dealer/70514/50444958.html
A36: =VLOOKUP(K36,Sheet4!B:C,2,FALSE) -> 奥德赛 | C36: 21.80万 | E36: 2 | F36: 有 | H36: 佛山市南海区桂城街道海八路G11千里发名车汇 | I36: 有 | J36: 9.23 | K36: http://www.che168.com/dealer/371720/50752834.html
A37: =VLOOKUP(K37,Sheet4!B:C,2,FALSE) -> 奥德赛 | C37: 19.20万 | E37: 2 | F37: 无 | H37: 东莞市寮步镇富竹山富荣路联合二手车交易市场V26-V29，V38-V41顺祥二手车展场... | I37: 有 | J37: 9.23 | K37: http://www.che168.com/dealer/109698/51694436.html
A38: =VLOOKUP(K38,Sheet4!B:C,2,FALSE) -> 奥德赛 | C38: 16.50万 | E38: 3 | F38: 无 | H38: 福建省泉州市鲤城区洋仕街36号泉州惠丰名车 | I38: 有 | J38: 9.23 | K38: http://www.che168.com/dealer/286456/51740501.html
A39: =VLOOKUP(K39,Sheet4!B:C,2,FALSE) -> 奥德赛 | C39: 12.50万 | E39: 1 | F39: 无 | H39: 哈尔滨市南岗区黄河路208号（会展中心院内）联盟二手车 | I39: 有 | J39: 9.23 | K39: http://www.che168.com/dealer/438521/49310301.html
A40: =VLOOKUP(K40,Sheet4!B:C,2,FALSE) -> 奥德赛 | C40: 9.98万 | E40: 2 | F40: 无 | H40: 深圳市宝安区创业二路与大宝路交汇处（洪浪北地铁B出口150米） | I40: 有 | J40: 9.23 | K40: http://www.che168.com/dealer/424659/51711502.html
A41: =VLOOKUP(K41,Sheet4!B:C,2,FALSE) -> 奥德赛 | C41: 11.98万 | E41: 2 | F41: 无 | H41: 广州市番禺区钟村街谢村工业区七街4号 | I41: 有 | J41: 9.23 | K41: http://www.che168.com/dealer/366664/51598920.html
... A55: =VLOOKUP(K55,Sheet4!B:C,2,FALSE) -> 奥德赛 | C55: 14.68万 | E55: 0 | F55: 无 | H55: 浙江省杭州市拱墅区康丰路8号（浙江省二手车交易市场B113号） | I55: 有 | J55: 9.23 | K55: http://www.che168.com/dealer/453612/51486538.html
A56: =VLOOKUP(K56,Sheet4!B:C,2,FALSE) -> 奥德赛 | C56: 16.88万 | E56: 此店铺点不开 | F56: 无 | H56: 无具体地址 | I56: 无 | J56: 无热度 | K56: http://www.che168.com/dealer/360983/51664967.html
A57: =VLOOKUP(K57,Sheet4!B:C,2,FALSE) -> 奥德赛 | C57: 12.75万 | E57: 0 | F57: 无 | H57: 无锡城南二手车市场F区01号展厅迅辉名车 | I57: 有 | J57: 9.23 | K57: http://www.che168.com/dealer/317493/51710961.html
...

Sheet Sheet3
A2: 售价 | B2: 星级店铺 | C2: 有无售后服务 | D2: 店铺地理位置 | E2: 销量 | F2: 有无质检 | G2: url
A3: 29.90万 | B3: 1 | C3: 有 | D3: 徐州市高新技术开发区聚盛汽车城金欧名车 | E3: 9.31 | F3: 有 | G3: http://www.che168.com/dealer/599647/50172903.html
A4: 19.80万 | B4: 2 | C4: 无 | D4: 陕西省西安市雁塔区岳旗寨安置楼科技西路与富源五路十字东北角 | E4: 9.31 | F4: 有 | G4: http://www.che168.com/dealer/548452/49847307.html
A5: 24.38万 | B5: 2 | C5: 有 | D5: 陕西省西安市雁塔区岳旗寨安置楼科技西路与富源五路十字东北角 | E5: 9.31 | F5: 有 | G5: http://www.che168.com/dealer/548452/51592748.html
A6: 20.28万 | B6: 2 | C6: 无 | D6: 陕西省西安市长安区东长安街1200号 | E6: 9.31 | F6: 有 | G6: http://www.che168.com/dealer/466721/51428068.html
A7: 31.98万 | B7: 0 | C7: 有 | D7: 四川省成都市金牛区羊西线蜀西路89号 | E7: 9.31 | F7: 有 | G7: http://www.che168.com/dealer/80399/51339513.html
A8: 17.70万 | B8: 1 | C8: 无 | D8: 哈尔滨市南岗区黄河路208号（会展中心院内）联盟二手车 | E8: 9.31 | F8: 有 | G8: http://www.che168.com/dealer/438521/51459617.html
A9: 17.97万 | B9: 0 | C9: 无 | D9: 西安市西咸新区沣东新城征和四路西段 | E9: 9.31 | F9: 有 | G9: http://www.che168.com/dealer/241965/51176708.html
A10: 18.80万 | B10: 2 | C10: 无 | D10: 海口市南海大道230号利星国际汽车城1号馆诚成互生 | E10: 9.31 | F10: 有 | G10: http://www.che168.com/dealer/130337/51380098.html
A11: 21.98万 | B11: 3 | C11: 无 | D11: 成都市高新区火车南站西路1626号（锦宏名车广场） | E11: 9.31 | F11: 有 | G11: http://www.che168.com/dealer/280393/50938397.html
A12: 18.80万 | B12: 0 | C12: 无 | D12: 西安市西咸新区沣东新城征和四路西段 | E12: 9.31 | F12: 有 | G12: http://www.che168.com/dealer/241965/50982296.html
A13: 16.28万 | B13: 0 | C13: 无 | D13: 广东省东莞市寮步镇寮步富荣路19号102室 | E13: 9.31 | F13: 有 | G13: http://www.che168.com/dealer/381107/51647611.html
A14: 19.36万 | B14: 1 | C14: 无 | D14: 南宁市南站大道21号智和村八组三产综合楼一层 | E14: 9.31 | F14: 有 | G14: http://www.che168.com/dealer/525859/50820037.html
... A30: 22.88万 | B30: 2 | C30: 无 | D30: 陕西省西安市长安区东长安街1200号 | E30: 9.31 | F30: 有 | G30: http://www.che168.com/dealer/466721/51740558.html
A31: 售价 | B31: 星级店铺 | C31: 有无售后服务 | D31: 店铺地理位置 | E31: 销量 | F31: 有无质检 | G31: url
A32: 54.88万 | B32: 2 | C32: 有 | D32: 北京市丰台区南四环西路123号北京旧车市场（花乡二手车市场）西精品厅中盛名... | E32: 9.23 | F32: 有 | G32: http://www.che168.com/dealer/201407/51675837.html
A33: 34.90万 | B33: 3 | C33: 无 | D33: 西安市西三环石桥车城内中心厅 | E33: 9.23 | F33: 有 | G33: http://www.che168.com/dealer/162138/51435402.html
A34: 15.90万 | B34: 2 | C34: 无 | D34: 吉林省长春市南关区卫星路与健民街交汇东行150米 | E34: 9.23 | F34: 有 | G34: http://www.che168.com/dealer/162714/51548661.html
A35: 44.30万 | B35: 1 | C35: 无 | D35: 重庆市九龙坡区迎宾大道11号红星美凯龙B1层卡乃驰汽车 | E35: 9.23 | F35: 有 | G35: http://www.che168.com/dealer/338744/51042906.html
A36: 6.80万 | B36: 2 | C36: 无 | D36: 西安市未央区东二环向北延伸线北辰大道与欧亚大道十字东北角 | E36: 9.23 | F36: 有 | G36: http://www.che168.com/dealer/170479/51571827.html
A37: 43.80万 | B37: 2 | C37: 无 | D37: 佛山市南海区桂城街道海八路G11千里发名车汇 | E37: 无热度 | F37: 有 | G37: http://www.che168.com/dealer/371720/51330760.html
A38: 37.99万 | B38: 0 | C38: 无 | D38: 西安市西咸新区沣东新城征和四路西段 | E38: 无热度 | F38: 有 | G38: http://www.che168.com/dealer/241965/51667298.html
A39: 40.98万 | B39: 0 | C39: 有 | D39: 西安市西咸新区沣东新城征和四路西段 | E39: 9.23 | F39: 有 | G39: http://www.che168.com/dealer/241965/51706772.html
A40: 45.80万 | B40: 2 | C40: 有 | D40: 河南省郑州市郑东新区商都路与潭南街交汇处 | E40: 9.23 | F40: 有 | G40: http://www.che168.com/dealer/152372/51428178.html
A41: 45.20万 | B41: 2 | C41: 有 | D41: 重庆市渝北区汽博中心转盘上越名车 | E41: 9.23 | F41: 有 | G41: http://www.che168.com/dealer/555905/51567324.html
A42: 40.90万 | B42: 1 | C42: 无 | D42: 徐州市高新技术开发区聚盛汽车城金欧名车 | E42: 9.23 | F42: 有 | G42: http://www.che168.com/dealer/599647/51274498.html
A43: 11.28万 | B43: 2 | C43: 无 | D43: 陕西省西安市长安区东长安街1200号 | E43: 9.23 | F43: 有 | G43: http://www.che168.com/dealer/466721/51711106.html
... A57: 39.50万 | B57: 0 | C57: 无 | D57: 西安市西咸新区沣东新城征和四路西段 | E57: 9.23 | F57: 有 | G57: http://www.che168.com/dealer/241965/51751348.html
A58: 售价 | B58: 星级店铺 | C58: 有无售后服务 | D58: 店铺地理位置 | E58: 销量 | F58: 有无质检 | G58: url
A59: 5.88万 | B59: 2 | C59: 无 | D59: 陕西省西安市长安区东长安街1200号 | E59: 9.3 | F59: 有 | G59: http://www.che168.com/dealer/466721/51691308.html
A60: 12.18万 | B60: 1 | C60: 有 | D60: 江西省南昌市南昌县迎宾中大道838号 | E60: 9.3 | F60: 有 | G60: http://www.che168.com/dealer/376288/50677735.html
A61: 14.58万 | B61: 3 | C61: 有 | D61: 成都市高新区火车南站西路1626号（锦宏名车广场） | E61: 9.3 | F61: 有 | G61: http://www.che168.com/dealer/280393/50286791.html
A62: 5.69万 | B62: 2 | C62: 无 | D62: 陕西省西安市长安区东长安街1200号 | E62: 9.3 | F62: 有 | G62: http://www.che168.com/dealer/466721/51638623.html
A63: 13.65万 | B63: 2 | C63: 有 | D63: 陕西省西安市长安区东长安街1200号 | E63: 9.3 | F63: 有 | G63: http://www.che168.com/dealer/466721/51462615.html
A64: 5.18万 | B64: 2 | C64: 无 | D64: 陕西省西安市长安区东长安街1200号 | E64: 9.3 | F64: 有 | G64: http://www.che168.com/dealer/466721/51710726.html
A65: 31.90万 | B65: 1 | C65: 无 | D65: 辽宁省沈阳市铁西区北二西路顶尚车城二楼 | E65: 9.23 | F65: 有 | G65: http://www.che168.com/dealer/530873/51377040.html
A66: 12.80万 | B66: 3 | C66: 有 | D66: 福建省泉州市鲤城区洋仕街36号泉州惠丰名车 | E66: 9.3 | F66: 有 | G66: http://www.che168.com/dealer/286456/51377942.html
A67: 13.80万 | B67: 2 | C67: 有 | D67: 山东省青岛市市南区燕儿岛路3号青岛东豪名车广场 | E67: 9.3 | F67: 有 | G67: http://www.che168.com/dealer/354927/51727774.html
A68: 7.80万 | B68: 2 | C68: 无 | D68: 无锡市新吴区金城东路五洲车城2号馆1层 | E68: 9.3 | F68: 有 | G68: http://www.che168.com/dealer/400899/51645675.html
A69: 9.98万 | B69: 0 | C69: 无 | D69: 市北区萍乡路55号陆海汽车交易市场一号展厅宏利达车行 | E69: 无热度 | F69: 有 | G69: http://www.che168.com/dealer/150832/51276607.html
...

Sheet Sheet4
B1: 标题链接 | C1: 标题
B2: http://www.che168.com/dealer/522686/50975959.html | C2: 思域
B3: http://www.che168.com/dealer/360661/50234187.html | C3: 思域
B4: http://www.che168.com/dealer/366664/51663344.html | C4: 思域
B5: http://www.che168.com/dealer/349857/51456651.html | C5: 思域
B6: http://www.che168.com/dealer/355413/51620390.html | C6: 思域
B7: http://www.che168.com/dealer/302732/51427339.html | C7: 思域
B8: http://www.che168.com/dealer/347357/51728885.html | C8: 思域
B9: http://www.che168.com/dealer/517025/51698768.html | C9: 思域
B10: http://www.che168.com/dealer/606334/51742318.html | C10: 思域
B11: http://www.che168.com/dealer/343793/50907119.html | C11: 思域
B12: http://www.che168.com/dealer/406545/51645855.html | C12: 思域
... B3016: http://www.che168.com/dealer/186578/51570247.html | C3016: 赛那SIENNA
